Workbook

Sheet Cover

Sheet Income Statement 
A1: Canadian Tire Corporation
A2: Historical Consolidated Income Statements (C$ Millions)
A4: Account | B4: 2021 | C4: 2022 | D4: 2023 | E4: 2024 | F4: 2025
A5: Revenue | B5: 14871 | C5: 17810.6 | D5: 16656.5 | E5: 15516 | F5: 16315.5
A6: Cost of Producing Revenue | B6: 9794.4 | C6: 11712.7 | D6: 10952.9 | E6: 10315.2 | F6: 10700.2
A7: Gross Margin | B7: 5076.6 | C7: 6097.9 | D7: 5703.6 | E7: 5200.8 | F7: 5615.3
A8: Other Expense (Income) | B8: 48.7 | C8: 61.6 | D8: 34.4 | E8: -290 | F8: 229
A9: Selling, General & Administrative Expenses | B9: 3599.3 | C9: =3502.5+719 -> 4221.5 | D9: =3675.7+771.2 -> 4446.9 | E9: =3240+731.6 -> 3971.6 | F9: =3470.6+741.7 -> 4212.3
A10: Operating Income | B10: =B7-B8-B9 -> 1428.6 | C10: =C7-C8-C9 -> 1814.8 | D10: =D7-D8-D9 -> 1222.3 | E10: =E7-E8-E9 -> 1519.2 | F10: =F7-F8-F9 -> 1174
A11: Net Finance Costs | B11: 256.5 | C11: 231 | D11: 321.5 | E11: 344.1 | F11: 295.5
A12: Income Before Taxes | B12: 1172.1 | C12: 1583.8 | D12: 572.8 | E12: 1175.1 | F12: 878.5
A13: Income Tax Expense | B13: 309.5 | C13: 401 | D13: 233.7 | E13: 259.6 | F13: 219.5
A14: Net Income | B14: 862.6 | C14: 1182.8 | D14: 339.1 | E14: 971.9 | F14: 609.7
A16: Note: 2025 net income includes discontinued operations. Net income from continuing operations was C$659.0 million.

Sheet Balance Sheet
A1: Canadian Tire Corporation
A2: Historical Consolidated Balance Sheets (C$ Millions)
A4: Account | B4: 2021 | C4: 2022 | D4: 2023 | E4: 2024 | F4: 2025
A5: Cash and cash equivalents | B5: 1327.2 | C5: 331.3 | D5: 311.2 | E5: 475.6 | F5: 553.5
A6: Trade & Other Receivables | B6: 973.6 | C6: 1309.9 | D6: 1151.3 | E6: 1263 | F6: 1053.2
A7: Short-term investments | B7: 643 | C7: 176.3 | D7: 177.2 | E7: 128.4 | F7: 148.5
A8: Loans receivable | B8: 5031.8 | C8: 6271.1 | D8: 6568.3 | E8: 6697.5 | F8: 6857.8
A9: Merchandise inventories | B9: 2312.9 | C9: 3216.1 | D9: 2693.7 | E9: 2558.3 | F9: 2417.5
A10: Income taxes recoverable | B10: 21.9 | C10: 27.4 | D10: 125.9 | E10: 9.3 | F10: 59.8
A11: Prepaid expenses and deposits | B11: 193.8 | C11: 195.7 | D11: 246.6 | E11: 212 | F11: 220.2
A12: Assets classified as held for sale | B12: 42.6 | C12: 2.6 | D12: 18.9 | E12: 3.8 | F12: 5.8
A13: Total Current Assets | B13: 10546.8 | C13: 11530.4 | D13: 11293.1 | E13: 11347.9 | F13: 11316.3
A15: Long-term receivables and other assets | B15: 631.9 | C15: 676.7 | D15: 645.8 | E15: 711.9 | F15: 703.4
A16: Long-term investments | B16: 146.2 | C16: 62.6 | D16: 108.2 | E16: 72.8 | F16: 71.4
... A21: Deferred income taxes | B21: 298.7 | C21: 143.4 | D21: 79.5 | E21: 65.9 | F21: 59.6
A22: Total Non-Current Assets | B22: 9830.3 | C22: 10572.9 | D22: 10685.2 | E22: 10892.7 | F22: =SUM(F15:F21) -> 10223.5
A24: Total Assets | B24: 20377.1 | C24: 22102.3 | D24: 21978.3 | E24: 22240.6 | F24: 21539.8
A26: Deposits | B26: 1228 | C26: 1226.3 | D26: 1041.7 | E26: 1171.4 | F26: 1109.4
A27: Trade and other payables | B27: 2508.3 | C27: 3200.9 | D27: 2689.4 | E27: 2931.4 | F27: 2811.6
A28: Provisions | B28: 196.7 | C28: 197.2 | D28: 219.9 | E28: 186.2 | F28: 255.6
A29: Short-term borrowings | B29: 165.4 | C29: 576.2 | D29: 965.7 | E29: 295.8 | F29: 295.1
A30: Loans | B30: 506.6 | C30: 472.9 | D30: 519.9 | E30: 563.2 | F30: 556.6
A31: Current portion of lease liabilities | B31: 329.9 | C31: 381.2 | D31: 378.5 | E31: 418.5 | F31: 355.6
A32: Income taxes payable | B32: 120.4 | C32: 47.1 | D32: 13.4 | E32: 88.5 | F32: 54.6
A33: Current portion of long-term debt | B33: 150.5 | C33: 1040.2 | D33: 560.5 | E33: 680.4 | F33: 758
A34: Total Current Liabilities | B34: 5205.8 | C34: 7147 | D34: 6389 | E34: 6335.4 | F34: =SUM(F26:F33) -> 6196.5
A36: Long-term provisions | B36: 70.3 | C36: 66.1 | D36: 59.8 | E36: 67.1 | F36: 60.2
A37: Long-term debt | B37: 4115.7 | C37: 3217.5 | D37: 4404 | E37: 3875.5 | F37: 3617.9
A38: Long-term deposits | B38: 2281.7 | C38: 1739.4 | D38: 2322.6 | E38: 2386 | F38: 2432.7
A39: Long-term lease liabilities | B39: 1896.6 | C39: 2026.4 | D39: 1986 | E39: 2071.6 | F39: 2086.3
A40: Deferred income taxes | B40: 122 | C40: 132.1 | D40: 182.1 | E40: 245.5 | F40: 130.9
A41: Other long-term liabilities | B41: 850.3 | C41: 734.6 | D41: 190 | E41: 171.2 | F41: 201.4
A42: Total Non-Current Liabilities | B42: 9336.6 | C42: 7916.1 | D42: 9144.5 | E42: 8816.9 | F42: =SUM(F36:F41) -> 8529.4
A44: Total Liabilities | B44: 14542.4 | C44: 15063.1 | D44: 15533.5 | E44: 15152.3 | F44: 14725.9
A46: Share capital | B46: 597 | C46: 587.8 | D46: 598.7 | E46: 625.9 | F46: 615.9
A47: Contributed surplus | B47: 2.9 | C47: 2.9 | D47: 2.9
A48: Accumulated other comprehensive (loss) | B48: -237.7 | C48: -42.4 | D48: -181.8 | E48: -85.3 | F48: 9.4
A49: Retained earnings | B49: 4136.9 | C49: 5070.2 | D49: 5128.2 | E49: 5614.4 | F49: 5230.3
A50: Equity attributable to shareholders of Canadian Tire Corporation | B50: 4499.1 | C50: 5618.5 | D50: 5548 | E50: 6155 | F50: 5855.6
A51: Non-controlling interests | B51: 1335.6 | C51: 1420.7 | D51: 896.8 | E51: 933.3 | F51: 958.3
...

Sheet Cash Flow Statement
A1: Canadian Tire Corporation
A2: Historical Consolidated Statements of Cash Flows (C$ Millions)
A4: Account | B4: 2021 | C4: 2022 | D4: 2023 | E4: 2024 | F4: 2025
A5: Cash Provided by Operating Activities
A6: Net Income | B6: 1260.7 | C6: 1182.8 | D6: 339.1 | E6: 971.9 | F6: 659
A7: Depreciation & Amortization | B7: 701.5 | C7: 743.5 | D7: 802.2 | E7: 785.1 | F7: 764
A8: Impairment Charges | B8: 5.3 | C8: 3.1 | D8: 6.3 | E8: 8.6 | F8: 27.9
A9: Income Taxes | B9: 441.2 | C9: 401 | D9: 233.7 | E9: 274.1 | F9: 219.5
A10: Net Finance Costs | B10: 222.5 | C10: 231 | D10: 321.5 | E10: 349 | F10: 295.5
A11: Other Non-Cash Adjustments | B11: -18.6 | C11: -1.3 | D11: 378.5 | E11: -279.6 | F11: -39.9
A12: Interest Paid | B12: -233 | C12: -254.6 | D12: -366.1 | E12: -413.6 | F12: -367.9
A13: Interest Received | B13: 13.9 | C13: 21.3 | D13: 38.8 | E13: 44 | F13: 28.6
A14: Income Taxes Paid | B14: -333.9 | C14: -529.3 | D14: -210.5 | E14: -46.9 | F14: -283.9
A15: Change in Loans Receivable | B15: -486.8 | C15: -657.1 | D15: -289.3 | E15: -139 | F15: -202.5
A16: Changes in Working Capital | B16: 241.6 | C16: -574.4 | D16: 99.5 | E16: 510.2 | F16: -148.2
A17: Net Cash from Operating Activities | B17: 1814.4 | C17: 566 | D17: 1353.7 | E17: 2063.8 | F17: 952.1
A19: Cash Used in Investing Activities
A20: Capital Expenditures | B20: -778.8 | C20: -834.6 | D20: -668.6 | E20: -636.8 | F20: -663.7
A21: Purchase of Investments | B21: -1185.4 | C21: -166.9 | D21: -210.9 | E21: -183 | F21: -331.7
A22: Sale / Maturity of Investments | B22: 1290.2 | C22: 713.1 | D22: 269.9 | E22: 271.2 | F22: 382
A23: Asset Sales | B23: 61.7 | C23: 5.2 | D23: 0.1 | E23: 321.1 | F23: 6.4
A24: Other Investing Activities | B24: -124.2 | C24: -46.7 | D24: -138.3 | E24: -36.6 | F24: 1245.8
A25: Net Cash from Investing Activities | B25: -736.5 | C25: -329.9 | D25: -747.8 | E25: -264.1 | F25: 638.8
A27: Cash Provided by (Used in) Financing Activities
A28: Dividends Paid | B28: -271.1 | C28: -325.8 | D28: -360.8 | E28: -359.8 | F28: -361.7
A29: Non-Controlling Interest Distributions | B29: -103.5 | C29: -143 | D29: -142.1 | E29: -70.3 | F29: -76.9
A30: Short-Term Borrowings | B30: -57.2 | C30: 468 | D30: 389.6 | E30: -669.9 | F30: -0.7
A31: Loans | B31: -79.1 | C31: 45.6 | D31: 47.2 | E31: 43.2 | F31: -6.7
A32: Long-Term Debt | B32: 8.2 | C32: -23.8 | D32: 709.9 | E32: -412.4 | F32: -184
A33: Lease Payments | B33: -365.3 | C33: -357.2 | D33: -425.2 | E33: -349.3 | F33: -383.2
A34: Share Repurchases | B34: -131.1 | C34: -425.4 | D34: -376.1 | E34: -29.8 | F34: -467.2
A35: Other Financing Activities | B35: 345.7 | C35: -899.9 | D35: -463.5 | E35: 213 | F35: -32.6
A36: Net Cash from Financing Activities | B36: -653.4 | C36: -1661.5 | D36: -621 | E36: -1635.3 | F36: -1513
A38: Net Increase (Decrease) in Cash | B38: 424.5 | C38: -1425.4 | D38: -15.1 | E38: 164.4 | F38: 77.9
A40: Beginning Cash | B40: 1327.2 | C40: 1751.7 | D40: 326.3 | E40: 311.2 | F40: 475.6
A42: Ending Cash | B42: 1751.7 | C42: 326.3 | D42: 311.2 | E42: 475.6 | F42: 553.5
A44: Note: Certain line items were consolidated to maintain consistent presentation across fiscal years (2021–2025).

Sheet Ratio Analysis
A1: Canadian Tire Corporation
A2: Historical Ratio Analysis (2021-2025)
A4: Ratio | B4: 2021 | C4: 2022 | D4: 2023 | E4: 2024 | F4: 2025 | G4: Key Observations
A5: Liquidity Ratios
A6: Current Ratio | B6: 2.03 | C6: 1.61 | D6: 1.77 | E6: 1.79 | F6: 1.83 | G6: Current ratio remained above 1.5 throughout the period, indicating Canadian Tire maintained a strong ability to meet its short-term obligations.
A7: Quick Ratio | B7: 0.57 | C7: 0.25 | D7: 0.26 | E7: 0.29 | F7: 0.28 | G7: Quick ratio stayed below 1.0 each year, suggesting the company relies heavily on inventory to meet short-term liabilities.
A8: Working Capital ($M) | B8: 5341 | C8: 4383.4 | D8: 4904.1 | E8: 5012.5 | F8: 5119.8 | G8: Working capital remained positive throughout the period, indicating the company maintained sufficient current assets to cover its short-term obligations.
A10: Profitability Ratios
A11: Gross Margin % | B11: 0.341 | C11: 0.342 | D11: 0.342 | E11: 0.335 | F11: 0.344 | G11: Gross margin remained stable at approximately 34% across all five years, reflecting consistent pricing power and cost management.
A12: Operating Margin % | B12: 0.096 | C12: 0.102 | D12: 0.073 | E12: 0.098 | F12: 0.072 | G12: Operating margin fluctuated between 7% and 10%, with lower profitability in 2023 and 2025 due to higher operating costs and weaker earnings.
A13: Net Profit Margin % | B13: 0.058 | C13: 0.066 | D13: 0.02 | E13: 0.063 | F13: 0.037 | G13: Net profit margin was volatile, falling sharply in 2023 before recovering in 2024, indicating fluctuations in overall profitability.
A14: Return on Assets (ROA) | C14: 0.056 | D14: 0.015 | E14: 0.044 | F14: 0.028 | G14: ROA declined after 2022, indicating lower efficiency in generating earnings from the company's asset base.
A15: Return on Equity (ROE) | C15: 0.184 | D15: 0.05 | E15: 0.144 | F15: 0.088 | G15: ROE varied significantly over the period, peaking in 2022 and declining afterward, reflecting changing profitability relative to shareholders' equity.
A17: Leverage Ratios
A18: Debt Ratio | B18: 0.714 | C18: 0.682 | D18: 0.707 | E18: 0.681 | F18: 0.684 | G18: The debt ratio remained relatively stable around 68–71%, indicating a consistently leveraged capital structure.
A19: Debt-to-Equity | B19: 2.49 | C19: 2.14 | D19: 2.41 | E19: 2.14 | F19: 2.16 | G19: Debt-to-equity remained relatively stable around 2.1–2.5, indicating consistent use of debt financing while maintaining a manageable capital structure.
A20: Equity Ratio | B20: 0.286 | C20: 0.318 | D20: 0.293 | E20: 0.319 | F20: 0.316 | G20: Equity financed approximately 29–32% of total assets throughout the period, remaining relatively consistent.
A22: Efficiency Ratios
A23: Inventory Turnover | C23: 4.24 | D23: 3.71 | E23: 3.93 | F23: 4.3 | G23: Inventory turnover improved after 2023, suggesting stronger inventory management and improved sales efficiency.
A24: Asset Turnover | C24: 0.84 | D24: 0.76 | E24: 0.7 | F24: 0.75 | G24: Asset turnover remained below 1.0 throughout the period, indicating the company generated less than one dollar of revenue for each dollar of assets.
A26: Growth Rates
A27: Revenue Growth % | C27: 0.198 | D27: -0.065 | E27: -0.068 | F27: 0.052 | G27: Revenue growth was negative in 2023 and 2024 before returning to positive growth in 2025, reflecting recovery in sales performance.
A28: Net Income Growth % | C28: 0.371 | D28: -0.713 | E28: 1.866 | F28: -0.373 | G28: Net income growth was highly volatile, with a significant decline in 2023, a strong rebound in 2024, and another decline in 2025.
A29: Total Assets Growth % | C29: 0.085 | D29: -0.006 | E29: 0.012 | F29: -0.032 | G29: Total assets remained relatively stable, with only modest year-over-year changes after 2022.
A30: Operating Cash Flow Growth % | C30: -0.69 | D30: 1.39 | E30: 0.52 | F30: -0.539 | G30: Operating cash flow experienced considerable fluctuations, highlighting variability in the company's cash generation despite generally positive operating cash flows.
A32: Notes:
A33: Ratio | B33: Formula
A34: Current Ratio | B34: Current Assets ÷ Current Liabilities
A35: Quick Ratio | B35: (Cash + Trade & Other Receivables + Short-term Investments) ÷ Current Liabilities
A36: Working Capital | B36: Current Assets − Current Liabilities
A37: Gross Margin | B37: Gross Profit ÷ Revenue
A38: Operating Margin | B38: Operating Income ÷ Revenue
A39: Net Profit Margin | B39: Net Income ÷ Revenue
A40: Return on Assets (ROA) | B40: Net Income ÷ Average Total Assets
A41: Return on Equity (ROE) | B41: Net Income ÷ Average Total Equity
A42: Debt Ratio | B42: Total Liabilities ÷ Total Assets
A43: Debt-to-Equity | B43: Total Liabilities ÷ Total Equity
A44: Equity Ratio | B44: Total Equity ÷ Total Assets
... A50: Operating Cash Flow Growth | B50: (Current Operating Cash Flow − Previous Operating Cash Flow) ÷ Previous Operating Cash Flow

Sheet Forecast Model
A1: Canadian Tire Corporation
A2: Forecast Model 2026 (C$ Millions)
A4: Forecasted Income Statement | B4: 2025 | C4: 2026 | D4: Assumptions
A5: Revenue | B5: 16315.5 | C5: =B5*(1+$E$5) -> 16968.12 | D5: Revenue Growth % | E5: 0.04
A6: Revenue Growth | C6: =E5 -> 0.04 | D6: Gross Margin % | E6: 0.344
A7: Cost of Revenue | B7: -10700.2 | C7: =C8-C5 -> -11131.087 | D7: SG&A % | E7: 0.258
A8: Gross Profit | B8: 5615.3 | C8: =C5*$E$6 -> 5837.0333 | D8: Interest Exp | E8: 300
A9: Other Expense (Income) | B9: 229 | C9: =B9 -> 229 | D9: Tax Rate % | E9: 0.25
A10: SG&A | B10: -4212.3 | C10: =-C5*$E$7 -> -4377.775
A11: Operating Income | B11: 1174 | C11: =C8-C9+C10 -> 1230.2583
A12: Net Finance Costs | B12: -295.5 | C12: =-$E$8 -> -300
A13: Income Before Taxes | B13: 878.5 | C13: =C11+C12 -> 930.25832
A14: Income Tax Expense | B14: -219.5 | C14: =-C13*$E$9 -> -232.56458
A15: Net Income | B15: 659 | C15: =C13+C14 -> 697.69374
A17: Forecasted Balance Sheet Statement | B17: 2025 | C17: 2026 | D17: Assumptions
A18: Cash & Cash Equivalents | B18: 553.5 | C18: =C46 -> 1353.0025 | D18: Receivables % of Revenue | E18: 0.065
A19: Trade & Other Receivables | B19: 1053.2 | C19: =$C$5*$E$18 -> 1102.9278 | D19: Inventory % of Revenue | E19: 0.148
A20: Merchandise Inventories | B20: 2417.5 | C20: =$C$5*$E$19 -> 2511.2818 | D20: Other Current Assets Growth % | E20: 0.02
A21: Other Current Assets | B21: 7292.1 | C21: =B21*(1+$E$20) -> 7437.942 | D21: Current Liabilities Growth % | E21: 0.025
A22: Total Current Assets | B22: 11316.3 | C22: =SUM(C18:C21) -> 12405.154 | D22: Depreciation % of Revenue | E22: 0.047
D23: CapEx % of Revenue | E23: 0.041
A24: Property & Equipment | B24: 5522.8 | C24: =B24+($C$5*$E$23)-($C$5*$E$22) -> 5420.9913
A25: Other Non-Current Assets | B25: 2676.7 | C25: =B25 -> 2676.7
A26: Total Non-Current Assets | B26: 8199.5 | C26: =SUM(C24:C25) -> 8097.6913
A28: Total Assets | B28: 21539.8 | C28: =C22+C26 -> 20502.845
A30: Current Liabilities | B30: 6196.5 | C30: =B30*(1+$E$21) -> 6351.4125
A31: Long-Term Debt | B31: 3617.9 | C31: =B31 -> 3617.9
A32: Other Non-Current Liabilities | B32: 4911.5 | C32: =B32 -> 4911.5
A33: Total Liabilities | B33: 14725.9 | C33: =SUM(C30:C32) -> 14880.812
A35: Total Equity | B35: 6813.9 | C35: =C28-C33 -> 5622.0328
A36: Total Liabilities & Equity | B36: 21539.8 | C36: =C33+C35 -> 20502.845
A37: Balance Check | C37: =C28-C36 -> 0
A39: Forecasted Cash Flow Statement | B39: 2025 | C39: 2026 | D39: Assumptions
A40: Net Income | B40: 659 | C40: =$C$15 -> 697.69374 | D40: Receivables % of Revenue | E40: 0.065
A41: Depreciation | B41: 764 | C41: =$C$5*$E$22 -> 797.50164 | D41: Inventory % of Revenue | E41: 0.148
A42: Operating Cash Flow | B42: 952.1 | C42: =C40+C41 -> 1495.1954 | D42: Other Current Assets Growth % | E42: 0.02
A43: Capital Expenditures | B43: -663.7 | C43: =-($C$5*$E$23) -> -695.69292 | D43: Current Liabilities Growth % | E43: 0.025
A44: Net Increase in Cash | B44: 77.9 | C44: =C42+C43 -> 799.50246 | D44: Depreciation % of Revenue | E44: 0.047
A45: Beginning Cash | B45: 553.5 | C45: =B18 -> 553.5 | D45: CapEx % of Revenue | E45: 0.041
A46: Ending Cash | B46: 553.5 | C46: =C45+C44 -> 1353.0025

Sheet Dashboard
E1: Canadian Tire Corporation
E2: Financial Analysis Dashboard
E3: 2021-2025 Actual | 2026 Forecast
A5: Revenue | B5: Net Income | C5: Total Assets | D5: Current Ratio | E5: ROE | F5: Ending Cash
A6: ='Forecast Model'!C5 -> 16968.12 | B6: ='Forecast Model'!C15 -> 697.69374 | C6: ='Forecast Model'!C28 -> 20502.845 | D6: ='Ratio Analysis'!F6 -> 1.83 | E6: ='Ratio Analysis'!F15 -> 0.088 | F6: ='Forecast Model'!C46 -> 1353.0025
G9: Financial Analysis Dashboard – Key Takeaways
G11: • Revenue is forecast to increase 4.0% in 2026 to C$16,968.1 million, indicating a return to moderate growth.
G13: •Net income from continuing operations is projected to increase from C$659.0 million in 2025 to C$697.7 million in 2026, reflecting improved profitability.
G15: • Total assets are forecast to decline to C$20,502.8 million in 2026 while total liabilities remain relatively stable, reflecting a more streamlined asset base.
G17: •The 2025 current ratio of 1.83 indicates the company maintained sufficient current assets to cover its short-term obligations.
G19: • Operating cash flow is projected to recover to C$1,495.2 million in 2026, supporting future investments and operations.
G21: • Gross margin remains stable at approximately 34.4%, demonstrating consistent operating performance.
G23: • Overall, the 2026 forecast suggests continued financial stability, with moderate revenue and earnings growth and an expected recovery in operating cash flow.
G26: Source: Canadian Tire Corporation Annual Reports (2021–2025)
G27: Forecast prepared using historical trend analysis and financial statement assumptions.
A333: Helper Tables:
A334: Revenue Trend | C334: Assets vs Liabilities | G334: Ratio Summary
A335: Year | B335: Revenue | C335: Year | D335: Assets | E335: Liabilities | G335: Ratio | H335: Value
A336: 2021 | B336: 14871 | C336: 2021 | D336: 20377.1 | E336: 14542.4 | G336: Current Ratio | H336: 1.83
A337: 2022 | B337: 17810.6 | C337: 2022 | D337: 22102.3 | E337: 15063.1 | G337: Quick Ratio | H337: 0.28
A338: 2023 | B338: 16656.5 | C338: 2023 | D338: 21978.3 | E338: 15533.5 | G338: Gross Margin | H338: 0.34
A339: 2024 | B339: 15516 | C339: 2024 | D339: 22240.6 | E339: 15152.3 | G339: Operating Margin | H339: 0.07
A340: 2025 | B340: 16315.5 | C340: 2025 | D340: 21539.8 | E340: 14725.9 | G340: Net Margin | H340: 0.04
A341: 2026F | B341: 16968.1 | C341: 2026F | D341: 22568.3 | E341: 14880.8 | G341: ROE | H341: 0.09
G342: Debt-to-Equity | H342: 2.16
A344: Net Income Trend | C344: Operating Cash Flow
A345: Year | B345: Net Income | C345: Year | D345: Operating Cash Flow
A346: 2021 | B346: 862.6 | C346: 2021 | D346: 1814.4
A347: 2022 | B347: 1182.8 | C347: 2022 | D347: 566
A348: 2023 | B348: 339.1 | C348: 2023 | D348: 1353.7
A349: 2024 | B349: 971.9 | C349: 2024 | D349: 2063.8
A350: 2025 | B350: 609.7 | C350: 2025 | D350: 952.1
A351: 2026F | B351: 697.7 | C351: 2026F | D351: 1495.2
